<?xml version="1.0" ?>

<sdf version="1.5">
  <model name="cart_soft_suspension">
    <link name="chassis">
      <pose>0 0 0.15  0 0 0</pose>
      <inertial>
        <pose>0.1 0 0  0 0 0</pose>
        <mass>10</mass>
        <inertia>
          <ixx>0.216666666666667</ixx>
          <iyy>0.841666666666667</iyy>
          <izz>1.04166666666667</izz>
          <ixy>0</ixy>
          <ixz>0</ixz>
          <iyz>0</iyz>
        </inertia>
      </inertial>
      <collision name="collision">
        <geometry>
          <box>
            <size>1.0 0.5 0.1</size>
          </box>
        </geometry>
      </collision>
      <visual name="visual">
        <geometry>
          <box>
            <size>1.0 0.5 0.1</size>
          </box>
        </geometry>
        <material>
          <script>
            <uri>file://media/materials/scripts/gazebo.material</uri>
            <name>Gazebo/Grey</name>
          </script>
        </material>
      </visual>
    </link>
    
    <link name="susp_front_right">
      <pose>0.5 -0.298 0.15  0 0 0</pose>
      <inertial>
        <mass>0.5</mass>
        <inertia>
          <ixx>0.000208333333333333</ixx>
          <iyy>0.000208333333333333</iyy>
          <izz>0.000208333333333333</izz>
          <ixy>0</ixy>
          <ixz>0</ixz>
          <iyz>0</iyz>
        </inertia>
      </inertial>
      <collision name="collision">
        <geometry>
          <box>
            <size>0.05 0.05 0.05</size>
          </box>
        </geometry>
      </collision>
      <visual name="visual">
        <geometry>
          <box>
            <size>0.05 0.05 0.05</size>
          </box>
        </geometry>
        <material>
          <script>
            <uri>file://media/materials/scripts/gazebo.material</uri>
            <name>Gazebo/Black</name>
          </script>
        </material>
      </visual>
    </link>
    <joint name="susp_front_right_prismatic" type="prismatic">
      <parent>chassis</parent>
      <child>susp_front_right</child>
      <axis>
        <xyz>0 0 -1</xyz>
        <limit>
          <lower>-0.0375</lower>
          <upper>0.0375</upper>
        </limit>
        <dynamics>
          <damping>100</damping>
          <spring_stiffness>2500</spring_stiffness>
          <spring_reference>0.05</spring_reference>
        </dynamics>
      </axis>
      <physics>
        <ode>
          <implicit_spring_damper>1</implicit_spring_damper>
        </ode>
      </physics>
    </joint>
    <link name="wheel_front_right">
      <pose>0.5 -0.298 0.15  -1.5707963267949 0 0</pose>
      <inertial>
        <mass>0.5</mass>
        <inertia>
          <ixx>0.00307916666666667</ixx>
          <iyy>0.00307916666666667</iyy>
          <izz>0.005625</izz>
          <ixy>0</ixy>
          <ixz>0</ixz>
          <iyz>0</iyz>
        </inertia>
      </inertial>
      <collision name="collision">
        <geometry>
          <cylinder>
            <radius>0.15</radius>
            <length>0.08</length>
          </cylinder>
        </geometry>
      </collision>
      <visual name="visual">
        <geometry>
          <cylinder>
            <radius>0.15</radius>
            <length>0.08</length>
          </cylinder>
        </geometry>
        <material>
          <script>
            <uri>file://media/materials/scripts/gazebo.material</uri>
            <name>Gazebo/Black</name>
          </script>
        </material>
      </visual>
    </link>
    <joint name="wheel_front_right_spin" type="revolute">
      <parent>susp_front_right</parent>
      <child>wheel_front_right</child>
      <axis>
        <xyz>0 0 1</xyz>
      </axis>
    </joint>
    
    <link name="susp_front_left">
      <pose>0.5 0.298 0.15  0 0 0</pose>
      <inertial>
        <mass>0.5</mass>
        <inertia>
          <ixx>0.000208333333333333</ixx>
          <iyy>0.000208333333333333</iyy>
          <izz>0.000208333333333333</izz>
          <ixy>0</ixy>
          <ixz>0</ixz>
          <iyz>0</iyz>
        </inertia>
      </inertial>
      <collision name="collision">
        <geometry>
          <box>
            <size>0.05 0.05 0.05</size>
          </box>
        </geometry>
      </collision>
      <visual name="visual">
        <geometry>
          <box>
            <size>0.05 0.05 0.05</size>
          </box>
        </geometry>
        <material>
          <script>
            <uri>file://media/materials/scripts/gazebo.material</uri>
            <name>Gazebo/Black</name>
          </script>
        </material>
      </visual>
    </link>
    <joint name="susp_front_left_prismatic" type="prismatic">
      <parent>chassis</parent>
      <child>susp_front_left</child>
      <axis>
        <xyz>0 0 -1</xyz>
        <limit>
          <lower>-0.0375</lower>
          <upper>0.0375</upper>
        </limit>
        <dynamics>
          <damping>100</damping>
          <spring_stiffness>2500</spring_stiffness>
          <spring_reference>0.05</spring_reference>
        </dynamics>
      </axis>
      <physics>
        <ode>
          <implicit_spring_damper>1</implicit_spring_damper>
        </ode>
      </physics>
    </joint>
    <link name="wheel_front_left">
      <pose>0.5 0.298 0.15  -1.5707963267949 0 0</pose>
      <inertial>
        <mass>0.5</mass>
        <inertia>
          <ixx>0.00307916666666667</ixx>
          <iyy>0.00307916666666667</iyy>
          <izz>0.005625</izz>
          <ixy>0</ixy>
          <ixz>0</ixz>
          <iyz>0</iyz>
        </inertia>
      </inertial>
      <collision name="collision">
        <geometry>
          <cylinder>
            <radius>0.15</radius>
            <length>0.08</length>
          </cylinder>
        </geometry>
      </collision>
      <visual name="visual">
        <geometry>
          <cylinder>
            <radius>0.15</radius>
            <length>0.08</length>
          </cylinder>
        </geometry>
        <material>
          <script>
            <uri>file://media/materials/scripts/gazebo.material</uri>
            <name>Gazebo/Black</name>
          </script>
        </material>
      </visual>
    </link>
    <joint name="wheel_front_left_spin" type="revolute">
      <parent>susp_front_left</parent>
      <child>wheel_front_left</child>
      <axis>
        <xyz>0 0 1</xyz>
      </axis>
    </joint>
    
    <link name="susp_rear_right">
      <pose>-0.5 -0.298 0.15  0 0 0</pose>
      <inertial>
        <mass>0.5</mass>
        <inertia>
          <ixx>0.000208333333333333</ixx>
          <iyy>0.000208333333333333</iyy>
          <izz>0.000208333333333333</izz>
          <ixy>0</ixy>
          <ixz>0</ixz>
          <iyz>0</iyz>
        </inertia>
      </inertial>
      <collision name="collision">
        <geometry>
          <box>
            <size>0.05 0.05 0.05</size>
          </box>
        </geometry>
      </collision>
      <visual name="visual">
        <geometry>
          <box>
            <size>0.05 0.05 0.05</size>
          </box>
        </geometry>
        <material>
          <script>
            <uri>file://media/materials/scripts/gazebo.material</uri>
            <name>Gazebo/Black</name>
          </script>
        </material>
      </visual>
    </link>
    <joint name="susp_rear_right_prismatic" type="prismatic">
      <parent>chassis</parent>
      <child>susp_rear_right</child>
      <axis>
        <xyz>0 0 -1</xyz>
        <limit>
          <lower>-0.0375</lower>
          <upper>0.0375</upper>
        </limit>
        <dynamics>
          <damping>100</damping>
          <spring_stiffness>2500</spring_stiffness>
          <spring_reference>0.05</spring_reference>
        </dynamics>
      </axis>
      <physics>
        <ode>
          <implicit_spring_damper>1</implicit_spring_damper>
        </ode>
      </physics>
    </joint>
    <link name="wheel_rear_right">
      <pose>-0.5 -0.298 0.15  -1.5707963267949 0 0</pose>
      <inertial>
        <mass>0.5</mass>
        <inertia>
          <ixx>0.00307916666666667</ixx>
          <iyy>0.00307916666666667</iyy>
          <izz>0.005625</izz>
          <ixy>0</ixy>
          <ixz>0</ixz>
          <iyz>0</iyz>
        </inertia>
      </inertial>
      <collision name="collision">
        <geometry>
          <cylinder>
            <radius>0.15</radius>
            <length>0.08</length>
          </cylinder>
        </geometry>
      </collision>
      <visual name="visual">
        <geometry>
          <cylinder>
            <radius>0.15</radius>
            <length>0.08</length>
          </cylinder>
        </geometry>
        <material>
          <script>
            <uri>file://media/materials/scripts/gazebo.material</uri>
            <name>Gazebo/Black</name>
          </script>
        </material>
      </visual>
    </link>
    <joint name="wheel_rear_right_spin" type="revolute">
      <parent>susp_rear_right</parent>
      <child>wheel_rear_right</child>
      <axis>
        <xyz>0 0 1</xyz>
      </axis>
    </joint>
    
    <link name="susp_rear_left">
      <pose>-0.5 0.298 0.15  0 0 0</pose>
      <inertial>
        <mass>0.5</mass>
        <inertia>
          <ixx>0.000208333333333333</ixx>
          <iyy>0.000208333333333333</iyy>
          <izz>0.000208333333333333</izz>
          <ixy>0</ixy>
          <ixz>0</ixz>
          <iyz>0</iyz>
        </inertia>
      </inertial>
      <collision name="collision">
        <geometry>
          <box>
            <size>0.05 0.05 0.05</size>
          </box>
        </geometry>
      </collision>
      <visual name="visual">
        <geometry>
          <box>
            <size>0.05 0.05 0.05</size>
          </box>
        </geometry>
        <material>
          <script>
            <uri>file://media/materials/scripts/gazebo.material</uri>
            <name>Gazebo/Black</name>
          </script>
        </material>
      </visual>
    </link>
    <joint name="susp_rear_left_prismatic" type="prismatic">
      <parent>chassis</parent>
      <child>susp_rear_left</child>
      <axis>
        <xyz>0 0 -1</xyz>
        <limit>
          <lower>-0.0375</lower>
          <upper>0.0375</upper>
        </limit>
        <dynamics>
          <damping>100</damping>
          <spring_stiffness>2500</spring_stiffness>
          <spring_reference>0.05</spring_reference>
        </dynamics>
      </axis>
      <physics>
        <ode>
          <implicit_spring_damper>1</implicit_spring_damper>
        </ode>
      </physics>
    </joint>
    <link name="wheel_rear_left">
      <pose>-0.5 0.298 0.15  -1.5707963267949 0 0</pose>
      <inertial>
        <mass>0.5</mass>
        <inertia>
          <ixx>0.00307916666666667</ixx>
          <iyy>0.00307916666666667</iyy>
          <izz>0.005625</izz>
          <ixy>0</ixy>
          <ixz>0</ixz>
          <iyz>0</iyz>
        </inertia>
      </inertial>
      <collision name="collision">
        <geometry>
          <cylinder>
            <radius>0.15</radius>
            <length>0.08</length>
          </cylinder>
        </geometry>
      </collision>
      <visual name="visual">
        <geometry>
          <cylinder>
            <radius>0.15</radius>
            <length>0.08</length>
          </cylinder>
        </geometry>
        <material>
          <script>
            <uri>file://media/materials/scripts/gazebo.material</uri>
            <name>Gazebo/Black</name>
          </script>
        </material>
      </visual>
    </link>
    <joint name="wheel_rear_left_spin" type="revolute">
      <parent>susp_rear_left</parent>
      <child>wheel_rear_left</child>
      <axis>
        <xyz>0 0 1</xyz>
      </axis>
    </joint>

    <plugin filename="libgazebo_ros_diff_drive.so" name="gazebo_ros_diff_drive">
      <ros>
          <namespace>/ds_car</namespace>
          <remapping>cmd_vel:=cmd_vel</remapping>
          <remapping>odom:=odom</remapping>
      </ros>
      <left_joint>wheel_rear_left_spin</left_joint>
      <right_joint>wheel_rear_right_spin</right_joint>
      <wheel_separation>0.6</wheel_separation>
      <wheel_radius>0.15</wheel_radius>
      <update_rate>50</update_rate>
      <publish_wheel_tf>true</publish_wheel_tf>
      <publish_odometry>true</publish_odometry>
      <odometry_topic>/ds_car/odom</odometry_topic>
      <odometry_frame>odom</odometry_frame>
      <robot_base_frame>chassis</robot_base_frame>
    </plugin>
    
    <link name="lidar_link">
      <pose>0.6 0 0.25 0 0 0</pose> <!-- 차체 앞부분 -->
      <sensor name="lidar_sensor" type="gpu_lidar">
        <update_rate>10</update_rate>
        <ray>
          <scan>
            <horizontal>
              <samples>720</samples> <!-- 720개 레이 (0.5도 간격) -->
              <resolution>1</resolution>
              <min_angle>-1.57</min_angle> <!-- -90도 -->
              <max_angle>1.57</max_angle> <!-- +90도 -->
            </horizontal>
          </scan>
          <range>
            <min>0.1</min> <!-- 최소 감지 거리 -->
            <max>10.0</max> <!-- 최대 감지 거리 -->
            <resolution>0.01</resolution>
          </range>
        </ray>
        <plugin name="gazebo_ros_laser" filename="libgazebo_ros_laser.so">
          <ros>
            <namespace>/ds_car</namespace>
            <remapping>scan:=lidar_scan</remapping>
          </ros>
          <output_type>sensor_msgs/LaserScan</output_type>
        </plugin>
      </sensor>
  </link>

  <link name="camera_link">
    <pose>0.6 0 0.35 0 0 0</pose> <!-- 차체 앞부분 -->
    <sensor name="camera_sensor" type="camera">
      <update_rate>30</update_rate>
      <camera>
        <horizontal_fov>1.57</horizontal_fov> <!-- 90도 FOV -->
        <image>
          <width>640</width>
          <height>480</height>
          <format>R8G8B8</format>
        </image>
        <clip>
          <near>0.02</near>
          <far>100</far>
        </clip>
      </camera>
      <plugin name="gazebo_ros_camera" filename="libgazebo_ros_camera.so">
        <ros>
          <namespace>/ds_car</namespace>
          <remapping>image_raw:=camera/image_raw</remapping>
        </ros>
      </plugin>
    </sensor>
  </link>


  </model>
</sdf>